2020-02-08 22:29:52,684 |   pack.madgraph.step |   INFO | starting file logging for topic: step
2020-02-08 22:29:52,752 |   pack.madgraph.step |  DEBUG | 
--------------
running one liner in container.
command: python steer_madgraph.py /Users/vlad/Documents/EPEprojects/yadage-tests/madgraph_pythia/workdir/init/proc_card_mg5.dat /Users/vlad/Documents/EPEprojects/yadage-tests/madgraph_pythia/workdir/madgraph/events.lhe -n 1000
--------------
    
2020-02-08 22:29:52,752 |   pack.madgraph.step |  DEBUG | 
--------------
run in docker container image: recast/madgraph
with env: default env
resources: []
--------------
    
2020-02-08 22:29:52,752 |   pack.madgraph.step |  DEBUG | do_auth: False do_cvmfs: False
2020-02-08 22:29:52,753 |   pack.madgraph.step |  DEBUG | rspec is
{
    "mounts": [
        {
            "type": "bind",
            "source": "/Users/vlad/Documents/EPEprojects/yadage-tests/madgraph_pythia/workdir/madgraph",
            "destination": "/Users/vlad/Documents/EPEprojects/yadage-tests/madgraph_pythia/workdir/madgraph",
            "readonly": false
        },
        {
            "type": "bind",
            "source": "/Users/vlad/Documents/EPEprojects/yadage-tests/madgraph_pythia/workdir/init",
            "destination": "/Users/vlad/Documents/EPEprojects/yadage-tests/madgraph_pythia/workdir/init",
            "readonly": false
        }
    ],
    "image": "recast/madgraph:2.6.7",
    "workdir": null,
    "argv": [
        "sh",
        "-c",
        "python steer_madgraph.py /Users/vlad/Documents/EPEprojects/yadage-tests/madgraph_pythia/workdir/init/proc_card_mg5.dat /Users/vlad/Documents/EPEprojects/yadage-tests/madgraph_pythia/workdir/madgraph/events.lhe -n 1000"
    ],
    "stdin": null,
    "tty": false
}
2020-02-08 22:29:52,753 |   pack.madgraph.step |  DEBUG | command: 
docker pull recast/madgraph:2.6.7
2020-02-08 22:29:52,753 |   pack.madgraph.step |  DEBUG | stdin if any: None
2020-02-08 22:29:52,756 |   pack.madgraph.step |  DEBUG | started subprocess with pid 6411. now wait to finish
2020-02-08 22:29:53,263 |   pack.madgraph.step |  DEBUG | process children: []
2020-02-08 22:29:54,240 |   pack.madgraph.step |  DEBUG | container execution subprocess finished. return code: 0
2020-02-08 22:29:54,240 |   pack.madgraph.step |  DEBUG | moving on from subprocess execution: docker pull recast/madgraph:2.6.7
2020-02-08 22:29:54,241 |   pack.madgraph.step |  DEBUG | finally for docker pull recast/madgraph:2.6.7
2020-02-08 22:29:54,241 |   pack.madgraph.step |  DEBUG | command: 
docker run --rm   --cidfile /Users/vlad/Documents/EPEprojects/yadage-tests/madgraph_pythia/workdir/madgraph/_packtivity/madgraph.cid     -v /Users/vlad/Documents/EPEprojects/yadage-tests/madgraph_pythia/workdir/madgraph:/Users/vlad/Documents/EPEprojects/yadage-tests/madgraph_pythia/workdir/madgraph:rw -v /Users/vlad/Documents/EPEprojects/yadage-tests/madgraph_pythia/workdir/init:/Users/vlad/Documents/EPEprojects/yadage-tests/madgraph_pythia/workdir/init:rw recast/madgraph:2.6.7 sh -c 'python steer_madgraph.py /Users/vlad/Documents/EPEprojects/yadage-tests/madgraph_pythia/workdir/init/proc_card_mg5.dat /Users/vlad/Documents/EPEprojects/yadage-tests/madgraph_pythia/workdir/madgraph/events.lhe -n 1000'
2020-02-08 22:29:54,242 |   pack.madgraph.step |  DEBUG | stdin if any: None
2020-02-08 22:29:54,246 |   pack.madgraph.step |  DEBUG | started subprocess with pid 6416. now wait to finish
2020-02-08 22:29:54,754 |   pack.madgraph.step |  DEBUG | process children: []
2020-02-08 22:30:15,115 |   pack.madgraph.step |  DEBUG | container execution subprocess finished. return code: 1
2020-02-08 22:30:15,115 |   pack.madgraph.step |  ERROR | non-zero return code raising exception
2020-02-08 22:30:15,116 |   pack.madgraph.step |  ERROR | subprocess failed. code: 1,  command docker run --rm   --cidfile /Users/vlad/Documents/EPEprojects/yadage-tests/madgraph_pythia/workdir/madgraph/_packtivity/madgraph.cid     -v /Users/vlad/Documents/EPEprojects/yadage-tests/madgraph_pythia/workdir/madgraph:/Users/vlad/Documents/EPEprojects/yadage-tests/madgraph_pythia/workdir/madgraph:rw -v /Users/vlad/Documents/EPEprojects/yadage-tests/madgraph_pythia/workdir/init:/Users/vlad/Documents/EPEprojects/yadage-tests/madgraph_pythia/workdir/init:rw recast/madgraph:2.6.7 sh -c 'python steer_madgraph.py /Users/vlad/Documents/EPEprojects/yadage-tests/madgraph_pythia/workdir/init/proc_card_mg5.dat /Users/vlad/Documents/EPEprojects/yadage-tests/madgraph_pythia/workdir/madgraph/events.lhe -n 1000'
Traceback (most recent call last):
  File "/usr/local/lib/python3.7/site-packages/packtivity/handlers/execution_handlers.py", line 331, in execute_and_tail_subprocess
    returncode=proc.returncode, cmd=command_string
subprocess.CalledProcessError: Command 'docker run --rm   --cidfile /Users/vlad/Documents/EPEprojects/yadage-tests/madgraph_pythia/workdir/madgraph/_packtivity/madgraph.cid     -v /Users/vlad/Documents/EPEprojects/yadage-tests/madgraph_pythia/workdir/madgraph:/Users/vlad/Documents/EPEprojects/yadage-tests/madgraph_pythia/workdir/madgraph:rw -v /Users/vlad/Documents/EPEprojects/yadage-tests/madgraph_pythia/workdir/init:/Users/vlad/Documents/EPEprojects/yadage-tests/madgraph_pythia/workdir/init:rw recast/madgraph:2.6.7 sh -c 'python steer_madgraph.py /Users/vlad/Documents/EPEprojects/yadage-tests/madgraph_pythia/workdir/init/proc_card_mg5.dat /Users/vlad/Documents/EPEprojects/yadage-tests/madgraph_pythia/workdir/madgraph/events.lhe -n 1000'' returned non-zero exit status 1.
2020-02-08 22:30:15,117 |   pack.madgraph.step |  DEBUG | finally for docker run --rm   --cidfile /Users/vlad/Documents/EPEprojects/yadage-tests/madgraph_pythia/workdir/madgraph/_packtivity/madgraph.cid     -v /Users/vlad/Documents/EPEprojects/yadage-tests/madgraph_pythia/workdir/madgraph:/Users/vlad/Documents/EPEprojects/yadage-tests/madgraph_pythia/workdir/madgraph:rw -v /Users/vlad/Documents/EPEprojects/yadage-tests/madgraph_pythia/workdir/init:/Users/vlad/Documents/EPEprojects/yadage-tests/madgraph_pythia/workdir/init:rw recast/madgraph:2.6.7 sh -c 'python steer_madgraph.py /Users/vlad/Documents/EPEprojects/yadage-tests/madgraph_pythia/workdir/init/proc_card_mg5.dat /Users/vlad/Documents/EPEprojects/yadage-tests/madgraph_pythia/workdir/madgraph/events.lhe -n 1000'
2020-02-08 22:30:15,117 |   pack.madgraph.step |  ERROR | job execution if job {'name': 'madgraph', 'wflow_node_id': '4fc235cb-cccd-4e1e-a74d-f6eeb3b1cda0', 'wflow_offset': '', 'wflow_stage': 'madgraph', 'wflow_stage_node_idx': 0, 'wflow_hints': {'is_purepub': False}} raise exception exception
Traceback (most recent call last):
  File "/usr/local/lib/python3.7/site-packages/packtivity/handlers/execution_handlers.py", line 331, in execute_and_tail_subprocess
    returncode=proc.returncode, cmd=command_string
subprocess.CalledProcessError: Command 'docker run --rm   --cidfile /Users/vlad/Documents/EPEprojects/yadage-tests/madgraph_pythia/workdir/madgraph/_packtivity/madgraph.cid     -v /Users/vlad/Documents/EPEprojects/yadage-tests/madgraph_pythia/workdir/madgraph:/Users/vlad/Documents/EPEprojects/yadage-tests/madgraph_pythia/workdir/madgraph:rw -v /Users/vlad/Documents/EPEprojects/yadage-tests/madgraph_pythia/workdir/init:/Users/vlad/Documents/EPEprojects/yadage-tests/madgraph_pythia/workdir/init:rw recast/madgraph:2.6.7 sh -c 'python steer_madgraph.py /Users/vlad/Documents/EPEprojects/yadage-tests/madgraph_pythia/workdir/init/proc_card_mg5.dat /Users/vlad/Documents/EPEprojects/yadage-tests/madgraph_pythia/workdir/madgraph/events.lhe -n 1000'' returned non-zero exit status 1.

During handling of the above exception, another exception occurred:

Traceback (most recent call last):
  File "/usr/local/lib/python3.7/site-packages/packtivity/syncbackends.py", line 187, in run_packtivity
    run_in_env(job, env, state, metadata, pack_config, exec_config)
  File "/usr/local/lib/python3.7/site-packages/packtivity/syncbackends.py", line 125, in run_in_env
    return handler(exec_config, environment, state, job, metadata)
  File "/usr/local/lib/python3.7/site-packages/packtivity/handlers/execution_handlers.py", line 448, in docker_enc_handler
    result = run(config, state, log, metadata, rspec)
  File "/usr/local/lib/python3.7/site-packages/packtivity/handlers/execution_handlers.py", line 399, in run_containers_in_docker_runtime
    logging_topic="run",
  File "/usr/local/lib/python3.7/site-packages/packtivity/handlers/execution_handlers.py", line 338, in execute_and_tail_subprocess
    raise RuntimeError("failed container execution subprocess. %s", command_string)
RuntimeError: ('failed container execution subprocess. %s', "docker run --rm   --cidfile /Users/vlad/Documents/EPEprojects/yadage-tests/madgraph_pythia/workdir/madgraph/_packtivity/madgraph.cid     -v /Users/vlad/Documents/EPEprojects/yadage-tests/madgraph_pythia/workdir/madgraph:/Users/vlad/Documents/EPEprojects/yadage-tests/madgraph_pythia/workdir/madgraph:rw -v /Users/vlad/Documents/EPEprojects/yadage-tests/madgraph_pythia/workdir/init:/Users/vlad/Documents/EPEprojects/yadage-tests/madgraph_pythia/workdir/init:rw recast/madgraph:2.6.7 sh -c 'python steer_madgraph.py /Users/vlad/Documents/EPEprojects/yadage-tests/madgraph_pythia/workdir/init/proc_card_mg5.dat /Users/vlad/Documents/EPEprojects/yadage-tests/madgraph_pythia/workdir/madgraph/events.lhe -n 1000'")
