2020-02-05 11:10:03,855 |   pack.madgraph.step |   INFO | starting file logging for topic: step
2020-02-05 11:10:03,923 |   pack.madgraph.step |  DEBUG | script is:
2020-02-05 11:10:03,923 |   pack.madgraph.step |  DEBUG | 
--------------
. ~/.profile
python steer_madgraph.py proc_card_mg5.dat events.lhe -n 100

--------------
2020-02-05 11:10:03,923 |   pack.madgraph.step |  DEBUG | 
--------------
run in docker container image: recast/madgraph
with env: default env
resources: []
--------------
    
2020-02-05 11:10:03,924 |   pack.madgraph.step |  DEBUG | do_auth: False do_cvmfs: False
2020-02-05 11:10:03,924 |   pack.madgraph.step |  DEBUG | rspec is
{
    "mounts": [
        {
            "type": "bind",
            "source": "/Users/vlad/Documents/EPEprojects/yadage-tests/madgraph_pythia/workdir/generation_madgraph_pythia/madgraph",
            "destination": "/Users/vlad/Documents/EPEprojects/yadage-tests/madgraph_pythia/workdir/generation_madgraph_pythia/madgraph",
            "readonly": false
        },
        {
            "type": "bind",
            "source": "/Users/vlad/Documents/EPEprojects/yadage-tests/madgraph_pythia/workdir/init",
            "destination": "/Users/vlad/Documents/EPEprojects/yadage-tests/madgraph_pythia/workdir/init",
            "readonly": false
        }
    ],
    "image": "recast/madgraph:2.6.7",
    "workdir": null,
    "argv": [
        "sh",
        "-c",
        "sh"
    ],
    "stdin": ". ~/.profile\npython steer_madgraph.py proc_card_mg5.dat events.lhe -n 100\n",
    "tty": false
}
2020-02-05 11:10:03,924 |   pack.madgraph.step |  DEBUG | command: 
docker pull recast/madgraph:2.6.7
2020-02-05 11:10:03,924 |   pack.madgraph.step |  DEBUG | stdin if any: None
2020-02-05 11:10:03,928 |   pack.madgraph.step |  DEBUG | started subprocess with pid 58284. now wait to finish
2020-02-05 11:10:04,433 |   pack.madgraph.step |  DEBUG | process children: []
2020-02-05 11:10:05,283 |   pack.madgraph.step |  DEBUG | container execution subprocess finished. return code: 0
2020-02-05 11:10:05,284 |   pack.madgraph.step |  DEBUG | moving on from subprocess execution: docker pull recast/madgraph:2.6.7
2020-02-05 11:10:05,284 |   pack.madgraph.step |  DEBUG | finally for docker pull recast/madgraph:2.6.7
2020-02-05 11:10:05,284 |   pack.madgraph.step |  DEBUG | command: 
docker run --rm -i  --cidfile /Users/vlad/Documents/EPEprojects/yadage-tests/madgraph_pythia/workdir/generation_madgraph_pythia/madgraph/_packtivity/madgraph.cid     -v /Users/vlad/Documents/EPEprojects/yadage-tests/madgraph_pythia/workdir/generation_madgraph_pythia/madgraph:/Users/vlad/Documents/EPEprojects/yadage-tests/madgraph_pythia/workdir/generation_madgraph_pythia/madgraph:rw -v /Users/vlad/Documents/EPEprojects/yadage-tests/madgraph_pythia/workdir/init:/Users/vlad/Documents/EPEprojects/yadage-tests/madgraph_pythia/workdir/init:rw recast/madgraph:2.6.7 sh -c sh
2020-02-05 11:10:05,285 |   pack.madgraph.step |  DEBUG | stdin if any: . ~/.profile
python steer_madgraph.py proc_card_mg5.dat events.lhe -n 100

2020-02-05 11:10:05,286 |   pack.madgraph.step |  DEBUG | stdin: 
. ~/.profile
python steer_madgraph.py proc_card_mg5.dat events.lhe -n 100

2020-02-05 11:10:05,287 |   pack.madgraph.step |  DEBUG | argv: ['docker', 'run', '--rm', '-i', '--cidfile', '/Users/vlad/Documents/EPEprojects/yadage-tests/madgraph_pythia/workdir/generation_madgraph_pythia/madgraph/_packtivity/madgraph.cid', '-v', '/Users/vlad/Documents/EPEprojects/yadage-tests/madgraph_pythia/workdir/generation_madgraph_pythia/madgraph:/Users/vlad/Documents/EPEprojects/yadage-tests/madgraph_pythia/workdir/generation_madgraph_pythia/madgraph:rw', '-v', '/Users/vlad/Documents/EPEprojects/yadage-tests/madgraph_pythia/workdir/init:/Users/vlad/Documents/EPEprojects/yadage-tests/madgraph_pythia/workdir/init:rw', 'recast/madgraph:2.6.7', 'sh', '-c', 'sh']
2020-02-05 11:10:05,289 |   pack.madgraph.step |  DEBUG | started subprocess with pid 58287. now wait to finish
2020-02-05 11:10:05,795 |   pack.madgraph.step |  DEBUG | process children: []
2020-02-05 11:10:06,471 |   pack.madgraph.step |  DEBUG | container execution subprocess finished. return code: 1
2020-02-05 11:10:06,472 |   pack.madgraph.step |  ERROR | non-zero return code raising exception
2020-02-05 11:10:06,472 |   pack.madgraph.step |  ERROR | subprocess failed. code: 1,  command docker run --rm -i  --cidfile /Users/vlad/Documents/EPEprojects/yadage-tests/madgraph_pythia/workdir/generation_madgraph_pythia/madgraph/_packtivity/madgraph.cid     -v /Users/vlad/Documents/EPEprojects/yadage-tests/madgraph_pythia/workdir/generation_madgraph_pythia/madgraph:/Users/vlad/Documents/EPEprojects/yadage-tests/madgraph_pythia/workdir/generation_madgraph_pythia/madgraph:rw -v /Users/vlad/Documents/EPEprojects/yadage-tests/madgraph_pythia/workdir/init:/Users/vlad/Documents/EPEprojects/yadage-tests/madgraph_pythia/workdir/init:rw recast/madgraph:2.6.7 sh -c sh
Traceback (most recent call last):
  File "/usr/local/lib/python3.7/site-packages/packtivity/handlers/execution_handlers.py", line 331, in execute_and_tail_subprocess
    returncode=proc.returncode, cmd=command_string
subprocess.CalledProcessError: Command 'docker run --rm -i  --cidfile /Users/vlad/Documents/EPEprojects/yadage-tests/madgraph_pythia/workdir/generation_madgraph_pythia/madgraph/_packtivity/madgraph.cid     -v /Users/vlad/Documents/EPEprojects/yadage-tests/madgraph_pythia/workdir/generation_madgraph_pythia/madgraph:/Users/vlad/Documents/EPEprojects/yadage-tests/madgraph_pythia/workdir/generation_madgraph_pythia/madgraph:rw -v /Users/vlad/Documents/EPEprojects/yadage-tests/madgraph_pythia/workdir/init:/Users/vlad/Documents/EPEprojects/yadage-tests/madgraph_pythia/workdir/init:rw recast/madgraph:2.6.7 sh -c sh' returned non-zero exit status 1.
2020-02-05 11:10:06,474 |   pack.madgraph.step |  DEBUG | finally for docker run --rm -i  --cidfile /Users/vlad/Documents/EPEprojects/yadage-tests/madgraph_pythia/workdir/generation_madgraph_pythia/madgraph/_packtivity/madgraph.cid     -v /Users/vlad/Documents/EPEprojects/yadage-tests/madgraph_pythia/workdir/generation_madgraph_pythia/madgraph:/Users/vlad/Documents/EPEprojects/yadage-tests/madgraph_pythia/workdir/generation_madgraph_pythia/madgraph:rw -v /Users/vlad/Documents/EPEprojects/yadage-tests/madgraph_pythia/workdir/init:/Users/vlad/Documents/EPEprojects/yadage-tests/madgraph_pythia/workdir/init:rw recast/madgraph:2.6.7 sh -c sh
2020-02-05 11:10:06,474 |   pack.madgraph.step |  ERROR | job execution if job {'name': 'madgraph', 'wflow_node_id': '952a2aaa-ba00-4d55-ab55-9684585e8752', 'wflow_offset': '/generation_madgraph_pythia/0', 'wflow_stage': 'madgraph', 'wflow_stage_node_idx': 0, 'wflow_hints': {'is_purepub': False}} raise exception exception
Traceback (most recent call last):
  File "/usr/local/lib/python3.7/site-packages/packtivity/handlers/execution_handlers.py", line 331, in execute_and_tail_subprocess
    returncode=proc.returncode, cmd=command_string
subprocess.CalledProcessError: Command 'docker run --rm -i  --cidfile /Users/vlad/Documents/EPEprojects/yadage-tests/madgraph_pythia/workdir/generation_madgraph_pythia/madgraph/_packtivity/madgraph.cid     -v /Users/vlad/Documents/EPEprojects/yadage-tests/madgraph_pythia/workdir/generation_madgraph_pythia/madgraph:/Users/vlad/Documents/EPEprojects/yadage-tests/madgraph_pythia/workdir/generation_madgraph_pythia/madgraph:rw -v /Users/vlad/Documents/EPEprojects/yadage-tests/madgraph_pythia/workdir/init:/Users/vlad/Documents/EPEprojects/yadage-tests/madgraph_pythia/workdir/init:rw recast/madgraph:2.6.7 sh -c sh' returned non-zero exit status 1.

During handling of the above exception, another exception occurred:

Traceback (most recent call last):
  File "/usr/local/lib/python3.7/site-packages/packtivity/syncbackends.py", line 187, in run_packtivity
    run_in_env(job, env, state, metadata, pack_config, exec_config)
  File "/usr/local/lib/python3.7/site-packages/packtivity/syncbackends.py", line 125, in run_in_env
    return handler(exec_config, environment, state, job, metadata)
  File "/usr/local/lib/python3.7/site-packages/packtivity/handlers/execution_handlers.py", line 448, in docker_enc_handler
    result = run(config, state, log, metadata, rspec)
  File "/usr/local/lib/python3.7/site-packages/packtivity/handlers/execution_handlers.py", line 399, in run_containers_in_docker_runtime
    logging_topic="run",
  File "/usr/local/lib/python3.7/site-packages/packtivity/handlers/execution_handlers.py", line 338, in execute_and_tail_subprocess
    raise RuntimeError("failed container execution subprocess. %s", command_string)
RuntimeError: ('failed container execution subprocess. %s', 'docker run --rm -i  --cidfile /Users/vlad/Documents/EPEprojects/yadage-tests/madgraph_pythia/workdir/generation_madgraph_pythia/madgraph/_packtivity/madgraph.cid     -v /Users/vlad/Documents/EPEprojects/yadage-tests/madgraph_pythia/workdir/generation_madgraph_pythia/madgraph:/Users/vlad/Documents/EPEprojects/yadage-tests/madgraph_pythia/workdir/generation_madgraph_pythia/madgraph:rw -v /Users/vlad/Documents/EPEprojects/yadage-tests/madgraph_pythia/workdir/init:/Users/vlad/Documents/EPEprojects/yadage-tests/madgraph_pythia/workdir/init:rw recast/madgraph:2.6.7 sh -c sh')
